Workbook
Name Slicer_Month: #N/A
Name Slicer_Region: #N/A

Sheet Dashboard
BJ11: =Pivots!AA11 -> Stonebridge Commercial | BK11: =Pivots!AB11 -> 60929.15
BJ12: =Pivots!AA12 -> Southcote Industries | BK12: =Pivots!AB12 -> 45112.95
BJ13: =Pivots!AA13 -> Larkspur Retailers | BK13: =Pivots!AB13 -> 43062.83 | BY13: =Pivots!A8 -> 984571.06
BJ16: Number of Customers
BJ17: =Pivots!$AI$5 -> 40
BJ22: =COUNTA(BC22:BC61) -> 0
BJ23: Average sales Value
BJ24: =Pivots!AL6 -> 18576.812
BJ29: Number of orders
BJ30: =Pivots!AL10 -> 53

Sheet Key Insights
C2: Key Insights
C4: 1. The annual sales target was missed by 8.8%. - Total sales was R984,571, against a target of R1,080,000 which resulted in a shortfall of about R95,429. - Only four months actually hit their number: January, July, October, and December. The other eight fell short.
C7: 2. The mid-year slump was not one continuous stretch; it had a gap in it. - April, May, and June all came in well under target, and things dipped again in August and September. - But July was actually a bright spot, clearing target by 3%.
C11: 3. Export is carrying the business, as it accounts for 54% of the total revenue. - Export brought in R531,576 which 54% of total revenue, more than every other region combined.
C14: 4. Nearly half the revenue comes from one country. - India accounted for R452,995, or 46% of total sales. - Pakistan is next at R77,523 which is less than a sixth of what India brought in.
C18: 5. The customer base is not dangerously concentrated, but worth watching. - Brackenfield Hardware & Supply Co. has 40 total customers, and the top 10 make up 41.6% of revenue. - Stonebridge Commercial alone accounts for 6.2%.
C22: 6. Two products are doing a lot of the heavy lifting. - Door Latch Set and PVC Elbow 20mm together brought in roughly R115,500, which is 11.7% of total sales. - Door Latch Set and PVC Elbow 20mm are well ahead of the rest of the top 10, which cluster much closer together, between R35K and R50K.
C25: 7. Saturdays sell; Mondays do not. - Saturday was the strongest day at R180,601, while Monday lagged at R114,849: a 57% gap between the two.
C29: Action Items
C31: 1. Find out what actually happened between April and September. - Three of those months missed target by more than 20%, and July's strong result right in the middle of that stretch suggests something specific changed that month, which is worth digging into rather than writing the whole period off as a slow season.
C35: 2. Don't lean so heavily on one region and one country. - Export and India each cover roughly half the revenue on their own, so any disruption there (including but not limited to shipping, tariffs, currency) would hit harder than it should. - Growing the North (4.6%) and South (5.4%) regions would help spread that risk out.
C39: 3. Look after the top 10 customers. - The top 10 customers account for 41.6% of revenue, so losing even one would show up immediately in the numbers. - A bit of proactive account management here goes a long way.
... C50: 6. Take another look at how targets get set. - February through April all carry a flat R100,000 target, and none of those months hit it. - Either the targets are too ambitious for that stretch of the year, or the way it is calculated needs a second look.

Sheet Pivots
A2: SUM OF SALES | D2: SALES BY MONTH | I2: SALES BY WEEK | M2: TOP 10 PRODUCTS | Q2: SALES BY REGION | V2: SALES BY COUNTRY | AA2: TOP 3 CUSTOMERS | AE2: AMOUNT OF ORDERS PER CUSTOMER | AI2: NUMBER OF CUSTOMERS | AP2: SALES BY MONTH
A4: Sum of Actual SALE | D4: Row Labels | E4: Sum of Actual SALE | I4: Row Labels | J4: Sum of Actual SALE | M4: Row Labels | N4: Sum of Actual SALE | Q4: Row Labels | R4: Sum of Actual SALE | V4: Row Labels | W4: Sum of Actual SALE | AA4: Row Labels | AB4: Sum of Actual SALE | AE4: Row Labels | AF4: Count of Actual SALE
A5: 984571.06 | D5: January | E5: 92118.79 | I5: 1 | J5: 5179.59 | M5: Self-Tapping Screw 25mm | N5: 34991.64 | Q5: Central | R5: 72920.48 | V5: India | W5: 452995.44 | AA5: Stonebridge Commercial | AB5: 60929.15 | AE5: Stonebridge Commercial | AF5: 35 | AI5: =COUNTA(AE5:AE44) -> 40 | AL5: Average Weekly Sales | AP5: Row Labels | AQ5: Sum of Actual SALE
D6: February | E6: 91137.05 | I6: 2 | J6: 21116.73 | M6: PVC Coupling 25mm | N6: 38232 | Q6: East | R6: 75939.73 | V6: Pakistan | W6: 77523.28 | AA6: Southcote Industries | AB6: 45112.95 | AE6: Overton Retail Solutions | AF6: 22 | AL6: =GETPIVOTDATA("Actual SALE",$I$4)/COUNTA(J5:J57) -> 18576.812 | AP6: January | AQ6: 92118.79
D7: March | E7: 97920.72 | I7: 3 | J7: 14261.19 | M7: Wing Nut M6 | N7: 38591.28 | Q7: Export | R7: 531575.62 | V7: Mexico | W7: 65776.76 | AA7: Larkspur Retailers | AB7: 43062.83 | AE7: Cobalt Point Supplies | AF7: 13 | AP7: February | AQ7: 91137.05
A8: =GETPIVOTDATA("Actual SALE",$A$4) -> 984571.06 | D8: April | E8: 72320.89 | I8: 4 | J8: 11433.2 | M8: Pipe Clamp 25mm | N8: 39659.76 | Q8: North | R8: 45081.78 | V8: Russia | W8: 63344.34 | AA8: Grand Total | AB8: 149104.93 | AE8: Meridian Hardware Co. | AF8: 13 | AP8: March | AQ8: 97920.72
D9: May | E9: 70511.76 | I9: 5 | J9: 33727.55 | M9: Corner Bracket 50mm | N9: 40883.04 | Q9: Northeast | R9: 83994.49 | V9: United Kingdom | W9: 50749.04 | AE9: Harrow Distribution | AF9: 21 | AL9: Number of orders | AP9: April | AQ9: 72320.89
D10: June | E10: 66727.4 | I10: 6 | J10: 34794.82 | M10: Hose Clamp 32mm | N10: 41055.3 | Q10: South | R10: 53277.57 | V10: Nigeria | W10: 39993.27 | AE10: Northfield Traders | AF10: 21 | AL10: =COUNTA(J5:J57) -> 53 | AP10: May | AQ10: 70511.76
D11: July | E11: 92661.55 | I11: 7 | J11: 32107.1 | M11: Anchor Bolt M10 | N11: 41580 | Q11: Western | R11: 121781.39 | V11: Ethiopia | W11: 39653.93 | AA11: =AA5 -> Stonebridge Commercial | AB11: =AB5 -> 60929.15 | AE11: Kingsmead Distribution | AF11: 7 | AP11: June | AQ11: 66727.4
D12: August | E12: 69125.75 | I12: 8 | J12: 11777.67 | M12: Eye Bolt M10 | N12: 49599.36 | Q12: Grand Total | R12: 984571.06 | V12: Brazil | W12: 39438.44 | AA12: =AA6 -> Southcote Industries | AB12: =AB6 -> 45112.95 | AE12: Vesterly Traders | AF12: 14 | AP12: July | AQ12: 92661.55
D13: September | E13: 78253.53 | I13: 9 | J13: 17571.59 | M13: PVC Elbow 20mm | N13: 57554.28 | V13: Saudi Arabia | W13: 38317.79 | AA13: =AA7 -> Larkspur Retailers | AB13: =AB7 -> 43062.83 | AE13: Alderman Retail Group | AF13: 6 | AP13: August | AQ13: 69125.75
D14: October | E14: 87136.37 | I14: 10 | J14: 17413.3 | M14: Door Latch Set | N14: 57968.64 | V14: South Africa | W14: 32808.02 | AE14: Talbot Street Merchants | AF14: 25 | AP14: September | AQ14: 78253.53
D15: November | E15: 75659.86 | I15: 11 | J15: 18811.39 | M15: Grand Total | N15: 440115.3 | V15: Bangladesh | W15: 31336.23 | AE15: Ironbridge Trading Co. | AF15: 23 | AP15: October | AQ15: 87136.37
D16: December | E16: 90997.39 | I16: 12 | J16: 29446.46 | V16: Germany | W16: 16810.72 | AE16: Hollowell Supply Co. | AF16: 9 | AP16: November | AQ16: 75659.86
D17: Grand Total | E17: 984571.06 | I17: 13 | J17: 22723.6 | V17: France | W17: 14337.4 | AE17: Draycott Wholesalers | AF17: 13 | AP17: December | AQ17: 90997.39
I18: 14 | J18: 13729.81 | V18: United States of America | W18: 13092.08 | AE18: Northgate Industries | AF18: 22
I19: 15 | J19: 27820.09 | V19: Indonesia | W19: 8394.32 | AE19: Ashworth Trading Group | AF19: 24
I20: 16 | J20: 9407.51 | V20: Grand Total | W20: 984571.06 | AE20: Vantage Point Retailers | AF20: 29
I21: 17 | J21: 22127.3 | AE21: Thornwell Trading | AF21: 25
I22: 18 | J22: 11809.4 | AE22: Ovenden & Sons | AF22: 27
I23: 19 | J23: 12750.54 | V23: Country | W23: Amount | AE23: Whitfield Distributors | AF23: 24
I24: 20 | J24: 19691.76 | V24: =V5 -> India | W24: {=W5:W19} -> 452995.44 | AE24: Pemberton & Associates | AF24: 15
I25: 21 | J25: 19171.71 | V25: =V6 -> Pakistan | W25: 77523.28 | AE25: Delacroix Wholesale | AF25: 32
I26: 22 | J26: 11617.86 | V26: =V7 -> Mexico | W26: 65776.76 | AE26: Redwood Mercantile | AF26: 25
I27: 23 | J27: 17000.62 | V27: =V8 -> Russia | W27: 63344.34 | AE27: Ridgeway Commercial | AF27: 22
I28: 24 | J28: 15273.35 | V28: =V9 -> United Kingdom | W28: 50749.04 | AE28: Fairstone Retail Group | AF28: 34
I29: 25 | J29: 23043.47 | V29: =V10 -> Nigeria | W29: 39993.27 | AE29: Silverline Wholesalers | AF29: 24
I30: 26 | J30: 13593.79 | V30: =V11 -> Ethiopia | W30: 39653.93 | AE30: Blackfriars Supply | AF30: 11
I31: 27 | J31: 13197.89 | V31: =V12 -> Brazil | W31: 39438.44 | AE31: Hendricks Mercantile | AF31: 31
I32: 28 | J32: 13311.34 | V32: =V13 -> Saudi Arabia | W32: 38317.79 | AE32: Millbrook Distribution | AF32: 15
I33: 29 | J33: 26662.81 | V33: =V14 -> South Africa | W33: 32808.02 | AE33: Marchbank Traders | AF33: 28
I34: 30 | J34: 15652.32 | V34: =V15 -> Bangladesh | W34: 31336.23 | AE34: Southcote Industries | AF34: 34
I35: 31 | J35: 27172.4 | V35: =V16 -> Germany | W35: 16810.72 | AE35: Fenwick Traders | AF35: 27
I36: 32 | J36: 6991.1 | V36: =V17 -> France | W36: 14337.4 | AE36: Coastal Fittings Ltd | AF36: 25
... I38: 34 | J38: 10403.35 | V38: =V19 -> Indonesia | W38: 8394.32 | AE38: Baxter & Kline Supplies | AF38: 25
I39: 35 | J39: 29524.29 | AE39: Larkspur Retailers | AF39: 28
I40: 36 | J40: 14336.82 | AE40: Cranfield & Co. | AF40: 17
I41: 37 | J41: 15584.3 | AE41: Ashcombe Traders | AF41: 15
I42: 38 | J42: 13437.32 | AE42: Kestrel Logistics | AF42: 8
I43: 39 | J43: 30057.11 | AE43: Union Cross Supply Co. | AF43: 8
...

Sheet Input Data
A1: DATA TABLE | N1: Brackenfield Hardware & Supply Co.
A4: DATE | B4: CUSTOMER NAME | C4: PRODUCT | D4: UNIT PRICE (R) | E4: QUANTITY | F4: Actual SALE | G4: Country | H4: Region | I4: Month | J4: Day | K4: Week | N4: Customer name Mapping Table | V4: Product name Mapping Table | AF4: Companies
A5: 44197 | B5: Stonebridge Commercial | C5: Eye Bolt M10 | D5: 156.96 | E5: 9 | F5: =InputData[[#This Row],[QUANTITY]]*InputData[[#This Row],[UNIT PRICE (R)]] -> 1412.64 | G5: =VLOOKUP(InputData[[#This Row],[CUSTOMER NAME]],Country[],2,0) -> India | H5: =VLOOKUP(InputData[[#This Row],[CUSTOMER NAME]],Country[],3,0) -> Western | I5: =TEXT(InputData[[#This Row],[DATE]],"mmmm") -> January | J5: =TEXT(InputData[[#This Row],[DATE]],"ddd") -> Fri | K5: =WEEKNUM(InputData[[#This Row],[DATE]]) -> 1 | N5: Customer01 | O5: Thornwell Trading | R5: CUSTOMER NAME | S5: Real Name | V5: Product01 | W5: Hex Bolt M8 | Z5: PRODUCT NAME | AA5: Real Name | AF5: Stonebridge Commercial
A6: 44197 | B6: Overton Retail Solutions | C6: Hose Clamp 32mm | D6: 141.57 | E6: 1 | F6: =InputData[[#This Row],[QUANTITY]]*InputData[[#This Row],[UNIT PRICE (R)]] -> 141.57 | G6: =VLOOKUP(InputData[[#This Row],[CUSTOMER NAME]],Country[],2,0) -> India | H6: =VLOOKUP(InputData[[#This Row],[CUSTOMER NAME]],Country[],3,0) -> South | I6: =TEXT(InputData[[#This Row],[DATE]],"mmmm") -> January | J6: =TEXT(InputData[[#This Row],[DATE]],"ddd") -> Fri | K6: =WEEKNUM(InputData[[#This Row],[DATE]]) -> 1 | N6: Customer02 | O6: Baxter & Kline Supplies | R6: Customer33 | S6: =_xlfn.XLOOKUP(R6,$N$5:$N$64,$O$5:$O$64,"Not Found") -> Stonebridge Commercial | V6: Product02 | W6: Hex Bolt M10 | Z6: Product24 | AA6: =_xlfn.XLOOKUP(Z6,$V$5:$V$48,$W$5:$W$48,"Not Found",0) -> Eye Bolt M10 | AF6: Overton Retail Solutions
A7: 44198 | B7: Cobalt Point Supplies | C7: Cable Tie 300mm | D7: 79.92 | E7: 15 | F7: =InputData[[#This Row],[QUANTITY]]*InputData[[#This Row],[UNIT PRICE (R)]] -> 1198.8 | G7: =VLOOKUP(InputData[[#This Row],[CUSTOMER NAME]],Country[],2,0) -> India | H7: =VLOOKUP(InputData[[#This Row],[CUSTOMER NAME]],Country[],3,0) -> North | I7: =TEXT(InputData[[#This Row],[DATE]],"mmmm") -> January | J7: =TEXT(InputData[[#This Row],[DATE]],"ddd") -> Sat | K7: =WEEKNUM(InputData[[#This Row],[DATE]]) -> 1 | N7: Customer03 | O7: Meridian Hardware Co. | R7: Customer29 | S7: =_xlfn.XLOOKUP(R7,$N$5:$N$64,$O$5:$O$64,"Not Found") -> Overton Retail Solutions | V7: Product03 | W7: Hex Bolt M12 | Z7: Product22 | AA7: =_xlfn.XLOOKUP(Z7,$V$5:$V$48,$W$5:$W$48,"Not Found",0) -> Hose Clamp 32mm | AF7: Cobalt Point Supplies
A8: 44198 | B8: Meridian Hardware Co. | C8: Shelf Bracket 200mm | D8: 119.7 | E8: 1 | F8: =InputData[[#This Row],[QUANTITY]]*InputData[[#This Row],[UNIT PRICE (R)]] -> 119.7 | G8: =VLOOKUP(InputData[[#This Row],[CUSTOMER NAME]],Country[],2,0) -> India | H8: =VLOOKUP(InputData[[#This Row],[CUSTOMER NAME]],Country[],3,0) -> Northeast | I8: =TEXT(InputData[[#This Row],[DATE]],"mmmm") -> January | J8: =TEXT(InputData[[#This Row],[DATE]],"ddd") -> Sat | K8: =WEEKNUM(InputData[[#This Row],[DATE]]) -> 1 | N8: Customer04 | O8: Coastal Fittings Ltd | R8: Customer31 | S8: =_xlfn.XLOOKUP(R8,$N$5:$N$64,$O$5:$O$64,"Not Found") -> Cobalt Point Supplies | V8: Product04 | W8: Carriage Bolt M8 | Z8: Product38 | AA8: =_xlfn.XLOOKUP(Z8,$V$5:$V$48,$W$5:$W$48,"Not Found",0) -> Cable Tie 300mm | AF8: Meridian Hardware Co.
A9: 44198 | B9: Harrow Distribution | C9: Rivet 4mm | D9: 15.72 | E9: 2 | F9: =InputData[[#This Row],[QUANTITY]]*InputData[[#This Row],[UNIT PRICE (R)]] -> 31.44 | G9: =VLOOKUP(InputData[[#This Row],[CUSTOMER NAME]],Country[],2,0) -> India | H9: =VLOOKUP(InputData[[#This Row],[CUSTOMER NAME]],Country[],3,0) -> Northeast | I9: =TEXT(InputData[[#This Row],[DATE]],"mmmm") -> January | J9: =TEXT(InputData[[#This Row],[DATE]],"ddd") -> Sat | K9: =WEEKNUM(InputData[[#This Row],[DATE]]) -> 1 | N9: Customer05 | O9: Harrow Distribution | R9: Customer03 | S9: =_xlfn.XLOOKUP(R9,$N$5:$N$64,$O$5:$O$64,"Not Found") -> Meridian Hardware Co. | V9: Product05 | W9: Wing Nut M6 | Z9: Product33 | AA9: =_xlfn.XLOOKUP(Z9,$V$5:$V$48,$W$5:$W$48,"Not Found",0) -> Shelf Bracket 200mm | AF9: Harrow Distribution
A10: 44198 | B10: Northfield Traders | C10: Self-Tapping Screw 25mm | D10: 164.28 | E10: 7 | F10: =InputData[[#This Row],[QUANTITY]]*InputData[[#This Row],[UNIT PRICE (R)]] -> 1149.96 | G10: =VLOOKUP(InputData[[#This Row],[CUSTOMER NAME]],Country[],2,0) -> India | H10: =VLOOKUP(InputData[[#This Row],[CUSTOMER NAME]],Country[],3,0) -> North | I10: =TEXT(InputData[[#This Row],[DATE]],"mmmm") -> January | J10: =TEXT(InputData[[#This Row],[DATE]],"ddd") -> Sat | K10: =WEEKNUM(InputData[[#This Row],[DATE]]) -> 1 | N10: Customer06 | O10: Vantage Point Retailers | R10: Customer05 | S10: =_xlfn.XLOOKUP(R10,$N$5:$N$64,$O$5:$O$64,"Not Found") -> Harrow Distribution | V10: Product06 | W10: Flange Nut M10 | Z10: Product15 | AA10: =_xlfn.XLOOKUP(Z10,$V$5:$V$48,$W$5:$W$48,"Not Found",0) -> Rivet 4mm | AF10: Northfield Traders
A11: 44198 | B11: Kingsmead Distribution | C11: Machine Screw M4 | D11: 122.08 | E11: 6 | F11: =InputData[[#This Row],[QUANTITY]]*InputData[[#This Row],[UNIT PRICE (R)]] -> 732.48 | G11: =VLOOKUP(InputData[[#This Row],[CUSTOMER NAME]],Country[],2,0) -> India | H11: =VLOOKUP(InputData[[#This Row],[CUSTOMER NAME]],Country[],3,0) -> Northeast | I11: =TEXT(InputData[[#This Row],[DATE]],"mmmm") -> January | J11: =TEXT(InputData[[#This Row],[DATE]],"ddd") -> Sat | K11: =WEEKNUM(InputData[[#This Row],[DATE]]) -> 1 | N11: Customer07 | O11: Kestrel Logistics | R11: Customer35 | S11: =_xlfn.XLOOKUP(R11,$N$5:$N$64,$O$5:$O$64,"Not Found") -> Northfield Traders | V11: Product07 | W11: Lock Washer M8 | Z11: Product10 | AA11: =_xlfn.XLOOKUP(Z11,$V$5:$V$48,$W$5:$W$48,"Not Found",0) -> Self-Tapping Screw 25mm | AF11: Kingsmead Distribution
A12: 44198 | B12: Vesterly Traders | C12: Rivet 4mm | D12: 15.72 | E12: 25 | F12: =InputData[[#This Row],[QUANTITY]]*InputData[[#This Row],[UNIT PRICE (R)]] -> 393 | G12: =VLOOKUP(InputData[[#This Row],[CUSTOMER NAME]],Country[],2,0) -> Germany | H12: =VLOOKUP(InputData[[#This Row],[CUSTOMER NAME]],Country[],3,0) -> Export | I12: =TEXT(InputData[[#This Row],[DATE]],"mmmm") -> January | J12: =TEXT(InputData[[#This Row],[DATE]],"ddd") -> Sat | K12: =WEEKNUM(InputData[[#This Row],[DATE]]) -> 1 | N12: Customer08 | O12: Silverline Wholesalers | R12: Customer38 | S12: =_xlfn.XLOOKUP(R12,$N$5:$N$64,$O$5:$O$64,"Not Found") -> Kingsmead Distribution | V12: Product08 | W12: Flat Washer M10 | Z12: Product13 | AA12: =_xlfn.XLOOKUP(Z12,$V$5:$V$48,$W$5:$W$48,"Not Found",0) -> Machine Screw M4 | AF12: Vesterly Traders
A13: 44199 | B13: Alderman Retail Group | C13: Cap Screw M6 | D13: 146.72 | E13: 21 | F13: =InputData[[#This Row],[QUANTITY]]*InputData[[#This Row],[UNIT PRICE (R)]] -> 3081.12 | G13: =VLOOKUP(InputData[[#This Row],[CUSTOMER NAME]],Country[],2,0) -> India | H13: =VLOOKUP(InputData[[#This Row],[CUSTOMER NAME]],Country[],3,0) -> Northeast | I13: =TEXT(InputData[[#This Row],[DATE]],"mmmm") -> January | J13: =TEXT(InputData[[#This Row],[DATE]],"ddd") -> Sun | K13: =WEEKNUM(InputData[[#This Row],[DATE]]) -> 2 | N13: Customer09 | O13: Northgate Industries | R13: Customer39 | S13: =_xlfn.XLOOKUP(R13,$N$5:$N$64,$O$5:$O$64,"Not Found") -> Vesterly Traders | V13: Product09 | W13: Threaded Rod M12 | Z13: Product15 | AA13: =_xlfn.XLOOKUP(Z13,$V$5:$V$48,$W$5:$W$48,"Not Found",0) -> Rivet 4mm | AF13: Alderman Retail Group
A14: 44199 | B14: Talbot Street Merchants | C14: Copper Pipe Fitting 15mm | D14: 83.08 | E14: 9 | F14: =InputData[[#This Row],[QUANTITY]]*InputData[[#This Row],[UNIT PRICE (R)]] -> 747.72 | G14: =VLOOKUP(InputData[[#This Row],[CUSTOMER NAME]],Country[],2,0) -> India | H14: =VLOOKUP(InputData[[#This Row],[CUSTOMER NAME]],Country[],3,0) -> Western | I14: =TEXT(InputData[[#This Row],[DATE]],"mmmm") -> January | J14: =TEXT(InputData[[#This Row],[DATE]],"ddd") -> Sun | K14: =WEEKNUM(InputData[[#This Row],[DATE]]) -> 2 | N14: Customer10 | O14: Ashcombe Traders | R14: Customer34 | S14: =_xlfn.XLOOKUP(R14,$N$5:$N$64,$O$5:$O$64,"Not Found") -> Alderman Retail Group | V14: Product10 | W14: Self-Tapping Screw 25mm | Z14: Product14 | AA14: =_xlfn.XLOOKUP(Z14,$V$5:$V$48,$W$5:$W$48,"Not Found",0) -> Cap Screw M6 | AF14: Talbot Street Merchants
A15: 44199 | B15: Ironbridge Trading Co. | C15: Cable Tie 300mm | D15: 79.92 | E15: 31 | F15: =InputData[[#This Row],[QUANTITY]]*InputData[[#This Row],[UNIT PRICE (R)]] -> 2477.52 | G15: =VLOOKUP(InputData[[#This Row],[CUSTOMER NAME]],Country[],2,0) -> United Kingdom | H15: =VLOOKUP(InputData[[#This Row],[CUSTOMER NAME]],Country[],3,0) -> Export | I15: =TEXT(InputData[[#This Row],[DATE]],"mmmm") -> January | J15: =TEXT(InputData[[#This Row],[DATE]],"ddd") -> Sun | K15: =WEEKNUM(InputData[[#This Row],[DATE]]) -> 2 | N15: Customer11 | O15: Redwood Mercantile | R15: Customer18 | S15: =_xlfn.XLOOKUP(R15,$N$5:$N$64,$O$5:$O$64,"Not Found") -> Talbot Street Merchants | V15: Product11 | W15: Wood Screw 40mm | Z15: Product43 | AA15: =_xlfn.XLOOKUP(Z15,$V$5:$V$48,$W$5:$W$48,"Not Found",0) -> Copper Pipe Fitting 15mm | AF15: Ironbridge Trading Co.
A16: 44199 | B16: Hollowell Supply Co. | C16: Carriage Bolt M8 | D16: 48.84 | E16: 5 | F16: =InputData[[#This Row],[QUANTITY]]*InputData[[#This Row],[UNIT PRICE (R)]] -> 244.2 | G16: =VLOOKUP(InputData[[#This Row],[CUSTOMER NAME]],Country[],2,0) -> United States of America | H16: =VLOOKUP(InputData[[#This Row],[CUSTOMER NAME]],Country[],3,0) -> Export | I16: =TEXT(InputData[[#This Row],[DATE]],"mmmm") -> January | J16: =TEXT(InputData[[#This Row],[DATE]],"ddd") -> Sun | K16: =WEEKNUM(InputData[[#This Row],[DATE]]) -> 2 | N16: Customer12 | O16: Bellview Enterprises | R16: Customer20 | S16: =_xlfn.XLOOKUP(R16,$N$5:$N$64,$O$5:$O$64,"Not Found") -> Ironbridge Trading Co. | V16: Product12 | W16: Drywall Screw 30mm | Z16: Product38 | AA16: =_xlfn.XLOOKUP(Z16,$V$5:$V$48,$W$5:$W$48,"Not Found",0) -> Cable Tie 300mm | AF16: Hollowell Supply Co.
A17: 44200 | B17: Draycott Wholesalers | C17: Butt Hinge 100mm | D17: 53.11 | E17: 1 | F17: =InputData[[#This Row],[QUANTITY]]*InputData[[#This Row],[UNIT PRICE (R)]] -> 53.11 | G17: =VLOOKUP(InputData[[#This Row],[CUSTOMER NAME]],Country[],2,0) -> Pakistan | H17: =VLOOKUP(InputData[[#This Row],[CUSTOMER NAME]],Country[],3,0) -> Export | I17: =TEXT(InputData[[#This Row],[DATE]],"mmmm") -> January | J17: =TEXT(InputData[[#This Row],[DATE]],"ddd") -> Mon | K17: =WEEKNUM(InputData[[#This Row],[DATE]]) -> 2 | N17: Customer13 | O17: Union Cross Supply Co. | R17: Customer37 | S17: =_xlfn.XLOOKUP(R17,$N$5:$N$64,$O$5:$O$64,"Not Found") -> Hollowell Supply Co. | V17: Product13 | W17: Machine Screw M4 | Z17: Product04 | AA17: =_xlfn.XLOOKUP(Z17,$V$5:$V$48,$W$5:$W$48,"Not Found",0) -> Carriage Bolt M8 | AF17: Draycott Wholesalers
... A44: 44213 | B44: Silverline Wholesalers | C44: Conduit Clamp 25mm | D44: 115.2 | E44: 4 | F44: =InputData[[#This Row],[QUANTITY]]*InputData[[#This Row],[UNIT PRICE (R)]] -> 460.8 | G44: =VLOOKUP(InputData[[#This Row],[CUSTOMER NAME]],Country[],2,0) -> United Kingdom | H44: =VLOOKUP(InputData[[#This Row],[CUSTOMER NAME]],Country[],3,0) -> Export | I44: =TEXT(InputData[[#This Row],[DATE]],"mmmm") -> January | J44: =TEXT(InputData[[#This Row],[DATE]],"ddd") -> Sun | K44: =WEEKNUM(InputData[[#This Row],[DATE]]) -> 4 | N44: Customer40 | O44: Radcliffe Mercantile | R44: Customer32 | S44: =_xlfn.XLOOKUP(R44,$N$5:$N$64,$O$5:$O$64,"Not Found") -> Draycott Wholesalers | V44: Product40 | W44: Conduit Clamp 25mm | Z44: Product14 | AA44: =_xlfn.XLOOKUP(Z44,$V$5:$V$48,$W$5:$W$48,"Not Found",0) -> Cap Screw M6 | AF44: Radcliffe Mercantile
A45: 44214 | B45: Vantage Point Retailers | C45: Flat Washer M10 | D45: 94.62 | E45: 9 | F45: =InputData[[#This Row],[QUANTITY]]*InputData[[#This Row],[UNIT PRICE (R)]] -> 851.58 | G45: =VLOOKUP(InputData[[#This Row],[CUSTOMER NAME]],Country[],2,0) -> Pakistan | H45: =VLOOKUP(InputData[[#This Row],[CUSTOMER NAME]],Country[],3,0) -> Export | I45: =TEXT(InputData[[#This Row],[DATE]],"mmmm") -> January | J45: =TEXT(InputData[[#This Row],[DATE]],"ddd") -> Mon | K45: =WEEKNUM(InputData[[#This Row],[DATE]]) -> 4 | N45: Customer41 | O45: Bramwell Industries | R45: Customer08 | S45: =_xlfn.XLOOKUP(R45,$N$5:$N$64,$O$5:$O$64,"Not Found") -> Silverline Wholesalers | V45: Product41 | W45: PVC Elbow 20mm | Z45: Product40 | AA45: =_xlfn.XLOOKUP(Z45,$V$5:$V$48,$W$5:$W$48,"Not Found",0) -> Conduit Clamp 25mm
A46: 44214 | B46: Whitfield Distributors | C46: U-Bolt M8 | D46: 149.46 | E46: 3 | F46: =InputData[[#This Row],[QUANTITY]]*InputData[[#This Row],[UNIT PRICE (R)]] -> 448.38 | G46: =VLOOKUP(InputData[[#This Row],[CUSTOMER NAME]],Country[],2,0) -> India | H46: =VLOOKUP(InputData[[#This Row],[CUSTOMER NAME]],Country[],3,0) -> Central | I46: =TEXT(InputData[[#This Row],[DATE]],"mmmm") -> January | J46: =TEXT(InputData[[#This Row],[DATE]],"ddd") -> Mon | K46: =WEEKNUM(InputData[[#This Row],[DATE]]) -> 4 | N46: Customer42 | O46: Castlerock Supply | R46: Customer06 | S46: =_xlfn.XLOOKUP(R46,$N$5:$N$64,$O$5:$O$64,"Not Found") -> Vantage Point Retailers | V46: Product42 | W46: PVC Coupling 25mm | Z46: Product08 | AA46: =_xlfn.XLOOKUP(Z46,$V$5:$V$48,$W$5:$W$48,"Not Found",0) -> Flat Washer M10
A47: 44214 | B47: Blackfriars Supply | C47: Brass Elbow Joint 20mm | D47: 82.08 | E47: 13 | F47: =InputData[[#This Row],[QUANTITY]]*InputData[[#This Row],[UNIT PRICE (R)]] -> 1067.04 | G47: =VLOOKUP(InputData[[#This Row],[CUSTOMER NAME]],Country[],2,0) -> India | H47: =VLOOKUP(InputData[[#This Row],[CUSTOMER NAME]],Country[],3,0) -> North | I47: =TEXT(InputData[[#This Row],[DATE]],"mmmm") -> January | J47: =TEXT(InputData[[#This Row],[DATE]],"ddd") -> Mon | K47: =WEEKNUM(InputData[[#This Row],[DATE]]) -> 4 | N47: Customer43 | O47: Ellsworth Traders | R47: Customer19 | S47: =_xlfn.XLOOKUP(R47,$N$5:$N$64,$O$5:$O$64,"Not Found") -> Whitfield Distributors | V47: Product43 | W47: Copper Pipe Fitting 15mm | Z47: Product23 | AA47: =_xlfn.XLOOKUP(Z47,$V$5:$V$48,$W$5:$W$48,"Not Found",0) -> U-Bolt M8
A48: 44215 | B48: Ironbridge Trading Co. | C48: T-Bracket 100mm | D48: 6.7 | E48: 6 | F48: =InputData[[#This Row],[QUANTITY]]*InputData[[#This Row],[UNIT PRICE (R)]] -> 40.2 | G48: =VLOOKUP(InputData[[#This Row],[CUSTOMER NAME]],Country[],2,0) -> United Kingdom | H48: =VLOOKUP(InputData[[#This Row],[CUSTOMER NAME]],Country[],3,0) -> Export | I48: =TEXT(InputData[[#This Row],[DATE]],"mmmm") -> January | J48: =TEXT(InputData[[#This Row],[DATE]],"ddd") -> Tue | K48: =WEEKNUM(InputData[[#This Row],[DATE]]) -> 4 | N48: Customer44 | O48: Greybourne Retailers | R48: Customer24 | S48: =_xlfn.XLOOKUP(R48,$N$5:$N$64,$O$5:$O$64,"Not Found") -> Blackfriars Supply | V48: Product44 | W48: Brass Elbow Joint 20mm | Z48: Product44 | AA48: =_xlfn.XLOOKUP(Z48,$V$5:$V$48,$W$5:$W$48,"Not Found",0) -> Brass Elbow Joint 20mm
A49: 44216 | B49: Northgate Industries | C49: L-Bracket 75mm | D49: 58.3 | E49: 4 | F49: =InputData[[#This Row],[QUANTITY]]*InputData[[#This Row],[UNIT PRICE (R)]] -> 233.2 | G49: =VLOOKUP(InputData[[#This Row],[CUSTOMER NAME]],Country[],2,0) -> Russia | H49: =VLOOKUP(InputData[[#This Row],[CUSTOMER NAME]],Country[],3,0) -> Export | I49: =TEXT(InputData[[#This Row],[DATE]],"mmmm") -> January | J49: =TEXT(InputData[[#This Row],[DATE]],"ddd") -> Wed | K49: =WEEKNUM(InputData[[#This Row],[DATE]]) -> 4 | N49: Customer45 | O49: Hawkridge Distribution | R49: Customer20 | S49: =_xlfn.XLOOKUP(R49,$N$5:$N$64,$O$5:$O$64,"Not Found") -> Ironbridge Trading Co. | Z49: Product35 | AA49: =_xlfn.XLOOKUP(Z49,$V$5:$V$48,$W$5:$W$48,"Not Found",0) -> T-Bracket 100mm
A50: 44216 | B50: Northfield Traders | C50: Toggle Bolt M6 | D50: 76.25 | E50: 4 | F50: =InputData[[#This Row],[QUANTITY]]*InputData[[#This Row],[UNIT PRICE (R)]] -> 305 | G50: =VLOOKUP(InputData[[#This Row],[CUSTOMER NAME]],Country[],2,0) -> India | H50: =VLOOKUP(InputData[[#This Row],[CUSTOMER NAME]],Country[],3,0) -> North | I50: =TEXT(InputData[[#This Row],[DATE]],"mmmm") -> January | J50: =TEXT(InputData[[#This Row],[DATE]],"ddd") -> Wed | K50: =WEEKNUM(InputData[[#This Row],[DATE]]) -> 4 | N50: Customer46 | O50: Underwood & Kline | R50: Customer09 | S50: =_xlfn.XLOOKUP(R50,$N$5:$N$64,$O$5:$O$64,"Not Found") -> Northgate Industries | Z50: Product34 | AA50: =_xlfn.XLOOKUP(Z50,$V$5:$V$48,$W$5:$W$48,"Not Found",0) -> L-Bracket 75mm
A51: 44216 | B51: Talbot Street Merchants | C51: Pipe Clamp 25mm | D51: 162.54 | E51: 2 | F51: =InputData[[#This Row],[QUANTITY]]*InputData[[#This Row],[UNIT PRICE (R)]] -> 325.08 | G51: =VLOOKUP(InputData[[#This Row],[CUSTOMER NAME]],Country[],2,0) -> India | H51: =VLOOKUP(InputData[[#This Row],[CUSTOMER NAME]],Country[],3,0) -> Western | I51: =TEXT(InputData[[#This Row],[DATE]],"mmmm") -> January | J51: =TEXT(InputData[[#This Row],[DATE]],"ddd") -> Wed | K51: =WEEKNUM(InputData[[#This Row],[DATE]]) -> 4 | N51: Customer47 | O51: Faircross Trading Co. | R51: Customer35 | S51: =_xlfn.XLOOKUP(R51,$N$5:$N$64,$O$5:$O$64,"Not Found") -> Northfield Traders | Z51: Product20 | AA51: =_xlfn.XLOOKUP(Z51,$V$5:$V$48,$W$5:$W$48,"Not Found",0) -> Toggle Bolt M6
A52: 44216 | B52: Hendricks Mercantile | C52: Cap Screw M6 | D52: 146.72 | E52: 7 | F52: =InputData[[#This Row],[QUANTITY]]*InputData[[#This Row],[UNIT PRICE (R)]] -> 1027.04 | G52: =VLOOKUP(InputData[[#This Row],[CUSTOMER NAME]],Country[],2,0) -> Ethiopia | H52: =VLOOKUP(InputData[[#This Row],[CUSTOMER NAME]],Country[],3,0) -> Export | I52: =TEXT(InputData[[#This Row],[DATE]],"mmmm") -> January | J52: =TEXT(InputData[[#This Row],[DATE]],"ddd") -> Wed | K52: =WEEKNUM(InputData[[#This Row],[DATE]]) -> 4 | N52: Customer48 | O52: Marlowe Commercial Group | R52: Customer18 | S52: =_xlfn.XLOOKUP(R52,$N$5:$N$64,$O$5:$O$64,"Not Found") -> Talbot Street Merchants | Z52: Product21 | AA52: =_xlfn.XLOOKUP(Z52,$V$5:$V$48,$W$5:$W$48,"Not Found",0) -> Pipe Clamp 25mm
A53: 44217 | B53: Pemberton & Associates | C53: Carriage Bolt M8 | D53: 48.84 | E53: 15 | F53: =InputData[[#This Row],[QUANTITY]]*InputData[[#This Row],[UNIT PRICE (R)]] -> 732.6 | G53: =VLOOKUP(InputData[[#This Row],[CUSTOMER NAME]],Country[],2,0) -> Pakistan | H53: =VLOOKUP(InputData[[#This Row],[CUSTOMER NAME]],Country[],3,0) -> Export | I53: =TEXT(InputData[[#This Row],[DATE]],"mmmm") -> January | J53: =TEXT(InputData[[#This Row],[DATE]],"ddd") -> Thu | K53: =WEEKNUM(InputData[[#This Row],[DATE]]) -> 4 | N53: Customer49 | O53: Denholm Supply Co. | R53: Customer25 | S53: =_xlfn.XLOOKUP(R53,$N$5:$N$64,$O$5:$O$64,"Not Found") -> Hendricks Mercantile | Z53: Product14 | AA53: =_xlfn.XLOOKUP(Z53,$V$5:$V$48,$W$5:$W$48,"Not Found",0) -> Cap Screw M6
A54: 44217 | B54: Kingsmead Distribution | C54: PVC Coupling 25mm | D54: 162 | E54: 6 | F54: =InputData[[#This Row],[QUANTITY]]*InputData[[#This Row],[UNIT PRICE (R)]] -> 972 | G54: =VLOOKUP(InputData[[#This Row],[CUSTOMER NAME]],Country[],2,0) -> India | H54: =VLOOKUP(InputData[[#This Row],[CUSTOMER NAME]],Country[],3,0) -> Northeast | I54: =TEXT(InputData[[#This Row],[DATE]],"mmmm") -> January | J54: =TEXT(InputData[[#This Row],[DATE]],"ddd") -> Thu | K54: =WEEKNUM(InputData[[#This Row],[DATE]]) -> 4 | N54: Customer50 | O54: Rushbrook Traders | R54: Customer36 | S54: =_xlfn.XLOOKUP(R54,$N$5:$N$64,$O$5:$O$64,"Not Found") -> Pemberton & Associates | Z54: Product04 | AA54: =_xlfn.XLOOKUP(Z54,$V$5:$V$48,$W$5:$W$48,"Not Found",0) -> Carriage Bolt M8
A55: 44217 | B55: Overton Retail Solutions | C55: Hex Bolt M12 | D55: 80.94 | E55: 9 | F55: =InputData[[#This Row],[QUANTITY]]*InputData[[#This Row],[UNIT PRICE (R)]] -> 728.46 | G55: =VLOOKUP(InputData[[#This Row],[CUSTOMER NAME]],Country[],2,0) -> India | H55: =VLOOKUP(InputData[[#This Row],[CUSTOMER NAME]],Country[],3,0) -> South | I55: =TEXT(InputData[[#This Row],[DATE]],"mmmm") -> January | J55: =TEXT(InputData[[#This Row],[DATE]],"ddd") -> Thu | K55: =WEEKNUM(InputData[[#This Row],[DATE]]) -> 4 | N55: Customer51 | O55: Calderwood Enterprises | R55: Customer38 | S55: =_xlfn.XLOOKUP(R55,$N$5:$N$64,$O$5:$O$64,"Not Found") -> Kingsmead Distribution | Z55: Product42 | AA55: =_xlfn.XLOOKUP(Z55,$V$5:$V$48,$W$5:$W$48,"Not Found",0) -> PVC Coupling 25mm
A56: 44218 | B56: Millbrook Distribution | C56: Hex Bolt M8 | D56: 103.88 | E56: 6 | F56: =InputData[[#This Row],[QUANTITY]]*InputData[[#This Row],[UNIT PRICE (R)]] -> 623.28 | G56: =VLOOKUP(InputData[[#This Row],[CUSTOMER NAME]],Country[],2,0) -> India | H56: =VLOOKUP(InputData[[#This Row],[CUSTOMER NAME]],Country[],3,0) -> South | I56: =TEXT(InputData[[#This Row],[DATE]],"mmmm") -> January | J56: =TEXT(InputData[[#This Row],[DATE]],"ddd") -> Fri | K56: =WEEKNUM(InputData[[#This Row],[DATE]]) -> 4 | N56: Customer52 | O56: Wexford Distribution | R56: Customer29 | S56: =_xlfn.XLOOKUP(R56,$N$5:$N$64,$O$5:$O$64,"Not Found") -> Overton Retail Solutions | Z56: Product03 | AA56: =_xlfn.XLOOKUP(Z56,$V$5:$V$48,$W$5:$W$48,"Not Found",0) -> Hex Bolt M12
A57: 44219 | B57: Redwood Mercantile | C57: Hex Bolt M10 | D57: 142.8 | E57: 5 | F57: =InputData[[#This Row],[QUANTITY]]*InputData[[#This Row],[UNIT PRICE (R)]] -> 714 | G57: =VLOOKUP(InputData[[#This Row],[CUSTOMER NAME]],Country[],2,0) -> Mexico | H57: =VLOOKUP(InputData[[#This Row],[CUSTOMER NAME]],Country[],3,0) -> Export | I57: =TEXT(InputData[[#This Row],[DATE]],"mmmm") -> January | J57: =TEXT(InputData[[#This Row],[DATE]],"ddd") -> Sat | K57: =WEEKNUM(InputData[[#This Row],[DATE]]) -> 4 | N57: Customer53 | O57: Ashgrove Mercantile | R57: Customer27 | S57: =_xlfn.XLOOKUP(R57,$N$5:$N$64,$O$5:$O$64,"Not Found") -> Millbrook Distribution | Z57: Product01 | AA57: =_xlfn.XLOOKUP(Z57,$V$5:$V$48,$W$5:$W$48,"Not Found",0) -> Hex Bolt M8
A58: 44219 | B58: Talbot Street Merchants | C58: Flat Washer M10 | D58: 94.62 | E58: 17 | F58: =InputData[[#This Row],[QUANTITY]]*InputData[[#This Row],[UNIT PRICE (R)]] -> 1608.54 | G58: =VLOOKUP(InputData[[#This Row],[CUSTOMER NAME]],Country[],2,0) -> India | H58: =VLOOKUP(InputData[[#This Row],[CUSTOMER NAME]],Country[],3,0) -> Western | I58: =TEXT(InputData[[#This Row],[DATE]],"mmmm") -> January | J58: =TEXT(InputData[[#This Row],[DATE]],"ddd") -> Sat | K58: =WEEKNUM(InputData[[#This Row],[DATE]]) -> 4 | N58: Customer54 | O58: Trentham Retail Co. | R58: Customer11 | S58: =_xlfn.XLOOKUP(R58,$N$5:$N$64,$O$5:$O$64,"Not Found") -> Redwood Mercantile | Z58: Product02 | AA58: =_xlfn.XLOOKUP(Z58,$V$5:$V$48,$W$5:$W$48,"Not Found",0) -> Hex Bolt M10
A59: 44219 | B59: Whitfield Distributors | C59: PVC Coupling 25mm | D59: 162 | E59: 8 | F59: =InputData[[#This Row],[QUANTITY]]*InputData[[#This Row],[UNIT PRICE (R)]] -> 1296 | G59: =VLOOKUP(InputData[[#This Row],[CUSTOMER NAME]],Country[],2,0) -> India | H59: =VLOOKUP(InputData[[#This Row],[CUSTOMER NAME]],Country[],3,0) -> Central | I59: =TEXT(InputData[[#This Row],[DATE]],"mmmm") -> January | J59: =TEXT(InputData[[#This Row],[DATE]],"ddd") -> Sat | K59: =WEEKNUM(InputData[[#This Row],[DATE]]) -> 4 | N59: Customer55 | O59: Blackthorn Traders | R59: Customer18 | S59: =_xlfn.XLOOKUP(R59,$N$5:$N$64,$O$5:$O$64,"Not Found") -> Talbot Street Merchants | Z59: Product08 | AA59: =_xlfn.XLOOKUP(Z59,$V$5:$V$48,$W$5:$W$48,"Not Found",0) -> Flat Washer M10
A60: 44220 | B60: Ashworth Trading Group | C60: Door Latch Set | D60: 201.28 | E60: 15 | F60: =InputData[[#This Row],[QUANTITY]]*InputData[[#This Row],[UNIT PRICE (R)]] -> 3019.2 | G60: =VLOOKUP(InputData[[#This Row],[CUSTOMER NAME]],Country[],2,0) -> India | H60: =VLOOKUP(InputData[[#This Row],[CUSTOMER NAME]],Country[],3,0) -> Northeast | I60: =TEXT(InputData[[#This Row],[DATE]],"mmmm") -> January | J60: =TEXT(InputData[[#This Row],[DATE]],"ddd") -> Sun | K60: =WEEKNUM(InputData[[#This Row],[DATE]]) -> 5 | N60: Customer56 | O60: Overbridge Supply | R60: Customer19 | S60: =_xlfn.XLOOKUP(R60,$N$5:$N$64,$O$5:$O$64,"Not Found") -> Whitfield Distributors | Z60: Product42 | AA60: =_xlfn.XLOOKUP(Z60,$V$5:$V$48,$W$5:$W$48,"Not Found",0) -> PVC Coupling 25mm
... A64: 44221 | B64: Delacroix Wholesale | C64: Cotter Pin 3mm | D64: 156.78 | E64: 14 | F64: =InputData[[#This Row],[QUANTITY]]*InputData[[#This Row],[UNIT PRICE (R)]] -> 2194.92 | G64: =VLOOKUP(InputData[[#This Row],[CUSTOMER NAME]],Country[],2,0) -> South Africa | H64: =VLOOKUP(InputData[[#This Row],[CUSTOMER NAME]],Country[],3,0) -> Export | I64: =TEXT(InputData[[#This Row],[DATE]],"mmmm") -> January | J64: =TEXT(InputData[[#This Row],[DATE]],"ddd") -> Mon | K64: =WEEKNUM(InputData[[#This Row],[DATE]]) -> 5 | N64: Customer60 | O64: Ravensworth Commercial | R64: Customer08 | S64: =_xlfn.XLOOKUP(R64,$N$5:$N$64,$O$5:$O$64,"Not Found") -> Silverline Wholesalers | Z64: Product34 | AA64: =_xlfn.XLOOKUP(Z64,$V$5:$V$48,$W$5:$W$48,"Not Found",0) -> L-Bracket 75mm
A65: 44222 | B65: Cobalt Point Supplies | C65: Eye Bolt M10 | D65: 156.96 | E65: 29 | F65: =InputData[[#This Row],[QUANTITY]]*InputData[[#This Row],[UNIT PRICE (R)]] -> 4551.84 | G65: =VLOOKUP(InputData[[#This Row],[CUSTOMER NAME]],Country[],2,0) -> India | H65: =VLOOKUP(InputData[[#This Row],[CUSTOMER NAME]],Country[],3,0) -> North | I65: =TEXT(InputData[[#This Row],[DATE]],"mmmm") -> January | J65: =TEXT(InputData[[#This Row],[DATE]],"ddd") -> Tue | K65: =WEEKNUM(InputData[[#This Row],[DATE]]) -> 5 | R65: Customer21 | S65: =_xlfn.XLOOKUP(R65,$N$5:$N$64,$O$5:$O$64,"Not Found") -> Delacroix Wholesale | Z65: Product17 | AA65: =_xlfn.XLOOKUP(Z65,$V$5:$V$48,$W$5:$W$48,"Not Found",0) -> Cotter Pin 3mm
A66: 44222 | B66: Vantage Point Retailers | C66: Brass Elbow Joint 20mm | D66: 82.08 | E66: 9 | F66: =InputData[[#This Row],[QUANTITY]]*InputData[[#This Row],[UNIT PRICE (R)]] -> 738.72 | G66: =VLOOKUP(InputData[[#This Row],[CUSTOMER NAME]],Country[],2,0) -> Pakistan | H66: =VLOOKUP(InputData[[#This Row],[CUSTOMER NAME]],Country[],3,0) -> Export | I66: =TEXT(InputData[[#This Row],[DATE]],"mmmm") -> January | J66: =TEXT(InputData[[#This Row],[DATE]],"ddd") -> Tue | K66: =WEEKNUM(InputData[[#This Row],[DATE]]) -> 5 | R66: Customer31 | S66: =_xlfn.XLOOKUP(R66,$N$5:$N$64,$O$5:$O$64,"Not Found") -> Cobalt Point Supplies | Z66: Product24 | AA66: =_xlfn.XLOOKUP(Z66,$V$5:$V$48,$W$5:$W$48,"Not Found",0) -> Eye Bolt M10
A67: 44222 | B67: Alderman Retail Group | C67: Hex Bolt M8 | D67: 103.88 | E67: 7 | F67: =InputData[[#This Row],[QUANTITY]]*InputData[[#This Row],[UNIT PRICE (R)]] -> 727.16 | G67: =VLOOKUP(InputData[[#This Row],[CUSTOMER NAME]],Country[],2,0) -> India | H67: =VLOOKUP(InputData[[#This Row],[CUSTOMER NAME]],Country[],3,0) -> Northeast | I67: =TEXT(InputData[[#This Row],[DATE]],"mmmm") -> January | J67: =TEXT(InputData[[#This Row],[DATE]],"ddd") -> Tue | K67: =WEEKNUM(InputData[[#This Row],[DATE]]) -> 5 | R67: Customer06 | S67: =_xlfn.XLOOKUP(R67,$N$5:$N$64,$O$5:$O$64,"Not Found") -> Vantage Point Retailers | Z67: Product44 | AA67: =_xlfn.XLOOKUP(Z67,$V$5:$V$48,$W$5:$W$48,"Not Found",0) -> Brass Elbow Joint 20mm
A68: 44222 | B68: Ridgeway Commercial | C68: Flange Nut M10 | D68: 85.5 | E68: 7 | F68: =InputData[[#This Row],[QUANTITY]]*InputData[[#This Row],[UNIT PRICE (R)]] -> 598.5 | G68: =VLOOKUP(InputData[[#This Row],[CUSTOMER NAME]],Country[],2,0) -> Saudi Arabia | H68: =VLOOKUP(InputData[[#This Row],[CUSTOMER NAME]],Country[],3,0) -> Export | I68: =TEXT(InputData[[#This Row],[DATE]],"mmmm") -> January | J68: =TEXT(InputData[[#This Row],[DATE]],"ddd") -> Tue | K68: =WEEKNUM(InputData[[#This Row],[DATE]]) -> 5 | R68: Customer34 | S68: =_xlfn.XLOOKUP(R68,$N$5:$N$64,$O$5:$O$64,"Not Found") -> Alderman Retail Group | Z68: Product01 | AA68: =_xlfn.XLOOKUP(Z68,$V$5:$V$48,$W$5:$W$48,"Not Found",0) -> Hex Bolt M8
A69: 44222 | B69: Talbot Street Merchants | C69: Self-Tapping Screw 25mm | D69: 164.28 | E69: 1 | F69: =InputData[[#This Row],[QUANTITY]]*InputData[[#This Row],[UNIT PRICE (R)]] -> 164.28 | G69: =VLOOKUP(InputData[[#This Row],[CUSTOMER NAME]],Country[],2,0) -> India | H69: =VLOOKUP(InputData[[#This Row],[CUSTOMER NAME]],Country[],3,0) -> Western | I69: =TEXT(InputData[[#This Row],[DATE]],"mmmm") -> January | J69: =TEXT(InputData[[#This Row],[DATE]],"ddd") -> Tue | K69: =WEEKNUM(InputData[[#This Row],[DATE]]) -> 5 | R69: Customer17 | S69: =_xlfn.XLOOKUP(R69,$N$5:$N$64,$O$5:$O$64,"Not Found") -> Ridgeway Commercial | Z69: Product06 | AA69: =_xlfn.XLOOKUP(Z69,$V$5:$V$48,$W$5:$W$48,"Not Found",0) -> Flange Nut M10
A70: 44223 | B70: Silverline Wholesalers | C70: Corner Bracket 50mm | D70: 117.48 | E70: 3 | F70: =InputData[[#This Row],[QUANTITY]]*InputData[[#This Row],[UNIT PRICE (R)]] -> 352.44 | G70: =VLOOKUP(InputData[[#This Row],[CUSTOMER NAME]],Country[],2,0) -> United Kingdom | H70: =VLOOKUP(InputData[[#This Row],[CUSTOMER NAME]],Country[],3,0) -> Export | I70: =TEXT(InputData[[#This Row],[DATE]],"mmmm") -> January | J70: =TEXT(InputData[[#This Row],[DATE]],"ddd") -> Wed | K70: =WEEKNUM(InputData[[#This Row],[DATE]]) -> 5 | R70: Customer18 | S70: =_xlfn.XLOOKUP(R70,$N$5:$N$64,$O$5:$O$64,"Not Found") -> Talbot Street Merchants | Z70: Product10 | AA70: =_xlfn.XLOOKUP(Z70,$V$5:$V$48,$W$5:$W$48,"Not Found",0) -> Self-Tapping Screw 25mm
A71: 44223 | B71: Marchbank Traders | C71: Conduit Clamp 25mm | D71: 115.2 | E71: 7 | F71: =InputData[[#This Row],[QUANTITY]]*InputData[[#This Row],[UNIT PRICE (R)]] -> 806.4 | G71: =VLOOKUP(InputData[[#This Row],[CUSTOMER NAME]],Country[],2,0) -> Brazil | H71: =VLOOKUP(InputData[[#This Row],[CUSTOMER NAME]],Country[],3,0) -> Export | I71: =TEXT(InputData[[#This Row],[DATE]],"mmmm") -> January | J71: =TEXT(InputData[[#This Row],[DATE]],"ddd") -> Wed | K71: =WEEKNUM(InputData[[#This Row],[DATE]]) -> 5 | R71: Customer08 | S71: =_xlfn.XLOOKUP(R71,$N$5:$N$64,$O$5:$O$64,"Not Found") -> Silverline Wholesalers | Z71: Product32 | AA71: =_xlfn.XLOOKUP(Z71,$V$5:$V$48,$W$5:$W$48,"Not Found",0) -> Corner Bracket 50mm
...

Sheet Target Analysis
B3: Month | C3: Month Name | D3: Target | E3: Actual | F3: Below Target | G3: Above Target | H3: Shortfall | J3: Analysis
B4: 1 | C4: January | D4: 90000 | E4: =VLOOKUP(TargetData[[#This Row],[Month Name]],Pivots!$D$5:$E$16,2,0) -> 92118.79 | F4: =IF(TargetData[[#This Row],[Actual]]<TargetData[[#This Row],[Target]],E4,"Above Target") -> Above Target | G4: =IF(TargetData[[#This Row],[Actual]]>TargetData[[#This Row],[Target]],TargetData[[#This Row],[Actual]],"Below Target") -> 92118.79 | H4: =TargetData[[#This Row],[Target]]-TargetData[[#This Row],[Actual]] -> -2118.79 | J4: % Target Missed | K4: =(TargetData[[#Totals],[Target]]-TargetData[[#Totals],[Actual]])/TargetData[[#Totals],[Target]] -> 0.08836013
B5: 2 | C5: February | D5: 100000 | E5: =VLOOKUP(TargetData[[#This Row],[Month Name]],Pivots!$D$5:$E$16,2,0) -> 91137.05 | F5: =IF(TargetData[[#This Row],[Actual]]<TargetData[[#This Row],[Target]],E5,"Above Target") -> 91137.05 | G5: =IF(TargetData[[#This Row],[Actual]]>TargetData[[#This Row],[Target]],TargetData[[#This Row],[Actual]],"Below Target") -> Below Target | H5: =TargetData[[#This Row],[Target]]-TargetData[[#This Row],[Actual]] -> 8862.95 | J5: Shortfall | K5: =TargetData[[#Totals],[Target]]-TargetData[[#Totals],[Actual]] -> 95428.94
B6: 3 | C6: March | D6: 100000 | E6: =VLOOKUP(TargetData[[#This Row],[Month Name]],Pivots!$D$5:$E$16,2,0) -> 97920.72 | F6: =IF(TargetData[[#This Row],[Actual]]<TargetData[[#This Row],[Target]],E6,"Above Target") -> 97920.72 | G6: =IF(TargetData[[#This Row],[Actual]]>TargetData[[#This Row],[Target]],TargetData[[#This Row],[Actual]],"Below Target") -> Below Target | H6: =TargetData[[#This Row],[Target]]-TargetData[[#This Row],[Actual]] -> 2079.28 | J6: Months with the highest Shortfall
B7: 4 | C7: April | D7: 100000 | E7: =VLOOKUP(TargetData[[#This Row],[Month Name]],Pivots!$D$5:$E$16,2,0) -> 72320.89 | F7: =IF(TargetData[[#This Row],[Actual]]<TargetData[[#This Row],[Target]],E7,"Above Target") -> 72320.89 | G7: =IF(TargetData[[#This Row],[Actual]]>TargetData[[#This Row],[Target]],TargetData[[#This Row],[Actual]],"Below Target") -> Below Target | H7: =TargetData[[#This Row],[Target]]-TargetData[[#This Row],[Actual]] -> 27679.11 | J7: April | K7: 27679.11
B8: 5 | C8: May | D8: 90000 | E8: =VLOOKUP(TargetData[[#This Row],[Month Name]],Pivots!$D$5:$E$16,2,0) -> 70511.76 | F8: =IF(TargetData[[#This Row],[Actual]]<TargetData[[#This Row],[Target]],E8,"Above Target") -> 70511.76 | G8: =IF(TargetData[[#This Row],[Actual]]>TargetData[[#This Row],[Target]],TargetData[[#This Row],[Actual]],"Below Target") -> Below Target | H8: =TargetData[[#This Row],[Target]]-TargetData[[#This Row],[Actual]] -> 19488.24 | J8: June | K8: 23272.6
B9: 6 | C9: June | D9: 90000 | E9: =VLOOKUP(TargetData[[#This Row],[Month Name]],Pivots!$D$5:$E$16,2,0) -> 66727.4 | F9: =IF(TargetData[[#This Row],[Actual]]<TargetData[[#This Row],[Target]],E9,"Above Target") -> 66727.4 | G9: =IF(TargetData[[#This Row],[Actual]]>TargetData[[#This Row],[Target]],TargetData[[#This Row],[Actual]],"Below Target") -> Below Target | H9: =TargetData[[#This Row],[Target]]-TargetData[[#This Row],[Actual]] -> 23272.6 | J9: August | K9: 20874.25
B10: 7 | C10: July | D10: 90000 | E10: =VLOOKUP(TargetData[[#This Row],[Month Name]],Pivots!$D$5:$E$16,2,0) -> 92661.55 | F10: =IF(TargetData[[#This Row],[Actual]]<TargetData[[#This Row],[Target]],E10,"Above Target") -> Above Target | G10: =IF(TargetData[[#This Row],[Actual]]>TargetData[[#This Row],[Target]],TargetData[[#This Row],[Actual]],"Below Target") -> 92661.55 | H10: =TargetData[[#This Row],[Target]]-TargetData[[#This Row],[Actual]] -> -2661.55
B11: 8 | C11: August | D11: 90000 | E11: =VLOOKUP(TargetData[[#This Row],[Month Name]],Pivots!$D$5:$E$16,2,0) -> 69125.75 | F11: =IF(TargetData[[#This Row],[Actual]]<TargetData[[#This Row],[Target]],E11,"Above Target") -> 69125.75 | G11: =IF(TargetData[[#This Row],[Actual]]>TargetData[[#This Row],[Target]],TargetData[[#This Row],[Actual]],"Below Target") -> Below Target | H11: =TargetData[[#This Row],[Target]]-TargetData[[#This Row],[Actual]] -> 20874.25
B12: 9 | C12: September | D12: 90000 | E12: =VLOOKUP(TargetData[[#This Row],[Month Name]],Pivots!$D$5:$E$16,2,0) -> 78253.53 | F12: =IF(TargetData[[#This Row],[Actual]]<TargetData[[#This Row],[Target]],E12,"Above Target") -> 78253.53 | G12: =IF(TargetData[[#This Row],[Actual]]>TargetData[[#This Row],[Target]],TargetData[[#This Row],[Actual]],"Below Target") -> Below Target | H12: =TargetData[[#This Row],[Target]]-TargetData[[#This Row],[Actual]] -> 11746.47
B13: 10 | C13: October | D13: 80000 | E13: =VLOOKUP(TargetData[[#This Row],[Month Name]],Pivots!$D$5:$E$16,2,0) -> 87136.37 | F13: =IF(TargetData[[#This Row],[Actual]]<TargetData[[#This Row],[Target]],E13,"Above Target") -> Above Target | G13: =IF(TargetData[[#This Row],[Actual]]>TargetData[[#This Row],[Target]],TargetData[[#This Row],[Actual]],"Below Target") -> 87136.37 | H13: =TargetData[[#This Row],[Target]]-TargetData[[#This Row],[Actual]] -> -7136.37
B14: 11 | C14: November | D14: 80000 | E14: =VLOOKUP(TargetData[[#This Row],[Month Name]],Pivots!$D$5:$E$16,2,0) -> 75659.86 | F14: =IF(TargetData[[#This Row],[Actual]]<TargetData[[#This Row],[Target]],E14,"Above Target") -> 75659.86 | G14: =IF(TargetData[[#This Row],[Actual]]>TargetData[[#This Row],[Target]],TargetData[[#This Row],[Actual]],"Below Target") -> Below Target | H14: =TargetData[[#This Row],[Target]]-TargetData[[#This Row],[Actual]] -> 4340.14
B15: 12 | C15: December | D15: 80000 | E15: =VLOOKUP(TargetData[[#This Row],[Month Name]],Pivots!$D$5:$E$16,2,0) -> 90997.39 | F15: =IF(TargetData[[#This Row],[Actual]]<TargetData[[#This Row],[Target]],E15,"Above Target") -> Above Target | G15: =IF(TargetData[[#This Row],[Actual]]>TargetData[[#This Row],[Target]],TargetData[[#This Row],[Actual]],"Below Target") -> 90997.39 | H15: =TargetData[[#This Row],[Target]]-TargetData[[#This Row],[Actual]] -> -10997.39
B16: Total | D16: =SUBTOTAL(109,TargetData[Target]) -> 1080000 | E16: =SUBTOTAL(109,TargetData[Actual]) -> 984571.06 | H16: =SUBTOTAL(109,TargetData[Shortfall]) -> 95428.94

Sheet Sheet1
A3: DATE | B3: CUSTOMER NAME | C3: PRODUCT | D3: UNIT PRICE (R) | E3: QUANTITY
A4: 44197 | B4: Customer01 | C4: Product01 | D4: 156.96 | E4: 9
A5: 44197 | B5: Customer02 | C5: Product02 | D5: 141.57 | E5: 1
A6: 44198 | B6: Customer03 | C6: Product03 | D6: 79.92 | E6: 15
A7: 44198 | B7: Customer04 | C7: Product04 | D7: 119.7 | E7: 1
A8: 44198 | B8: Customer05 | C8: Product05 | D8: 15.72 | E8: 2
A9: 44198 | B9: Customer06 | C9: Product06 | D9: 164.28 | E9: 7
A10: 44198 | B10: Customer07 | C10: Product07 | D10: 122.08 | E10: 6
A11: 44198 | B11: Customer08 | C11: Product08 | D11: 15.72 | E11: 25
A12: 44199 | B12: Customer09 | C12: Product09 | D12: 146.72 | E12: 21
A13: 44199 | B13: Customer10 | C13: Product10 | D13: 83.08 | E13: 9
A14: 44199 | B14: Customer11 | C14: Product11 | D14: 79.92 | E14: 31
A15: 44199 | B15: Customer12 | C15: Product12 | D15: 48.84 | E15: 5
... A27: 44205 | B27: Customer24 | C27: Product24 | D27: 117.48 | E27: 12
B28: Customer25 | C28: Product25
C29: Product26

Sheet Customer
A1: Customer Name | B1: Country | C1: Region | H1: Real name
A2: Thornwell Trading | B2: Nigeria | C2: Export | G2: Customer01 | H2: =_xlfn.XLOOKUP(G2,'Input Data'!$N$5:$N$64,'Input Data'!$O$5:$O$64,"Not found",0) -> Thornwell Trading
A3: Baxter & Kline Supplies | B3: Bangladesh | C3: Export | G3: Customer02 | H3: =_xlfn.XLOOKUP(G3,'Input Data'!$N$5:$N$64,'Input Data'!$O$5:$O$64,"Not found",0) -> Baxter & Kline Supplies
A4: Meridian Hardware Co. | B4: India | C4: Northeast | G4: Customer03 | H4: =_xlfn.XLOOKUP(G4,'Input Data'!$N$5:$N$64,'Input Data'!$O$5:$O$64,"Not found",0) -> Meridian Hardware Co.
A5: Coastal Fittings Ltd | B5: Saudi Arabia | C5: Export | G5: Customer04 | H5: =_xlfn.XLOOKUP(G5,'Input Data'!$N$5:$N$64,'Input Data'!$O$5:$O$64,"Not found",0) -> Coastal Fittings Ltd
A6: Harrow Distribution | B6: India | C6: Northeast | G6: Customer05 | H6: =_xlfn.XLOOKUP(G6,'Input Data'!$N$5:$N$64,'Input Data'!$O$5:$O$64,"Not found",0) -> Harrow Distribution
A7: Vantage Point Retailers | B7: Pakistan | C7: Export | G7: Customer06 | H7: =_xlfn.XLOOKUP(G7,'Input Data'!$N$5:$N$64,'Input Data'!$O$5:$O$64,"Not found",0) -> Vantage Point Retailers
A8: Kestrel Logistics | B8: Indonesia | C8: Export | G8: Customer07 | H8: =_xlfn.XLOOKUP(G8,'Input Data'!$N$5:$N$64,'Input Data'!$O$5:$O$64,"Not found",0) -> Kestrel Logistics
A9: Silverline Wholesalers | B9: United Kingdom | C9: Export | G9: Customer08 | H9: =_xlfn.XLOOKUP(G9,'Input Data'!$N$5:$N$64,'Input Data'!$O$5:$O$64,"Not found",0) -> Silverline Wholesalers
A10: Northgate Industries | B10: Russia | C10: Export | G10: Customer09 | H10: =_xlfn.XLOOKUP(G10,'Input Data'!$N$5:$N$64,'Input Data'!$O$5:$O$64,"Not found",0) -> Northgate Industries
A11: Ashcombe Traders | B11: India | C11: South | G11: Customer10 | H11: =_xlfn.XLOOKUP(G11,'Input Data'!$N$5:$N$64,'Input Data'!$O$5:$O$64,"Not found",0) -> Ashcombe Traders
A12: Redwood Mercantile | B12: Mexico | C12: Export | G12: Customer11 | H12: =_xlfn.XLOOKUP(G12,'Input Data'!$N$5:$N$64,'Input Data'!$O$5:$O$64,"Not found",0) -> Redwood Mercantile
A13: Bellview Enterprises | B13: India | C13: Central | G13: Customer12 | H13: =_xlfn.XLOOKUP(G13,'Input Data'!$N$5:$N$64,'Input Data'!$O$5:$O$64,"Not found",0) -> Bellview Enterprises
... A41: Radcliffe Mercantile | B41: United States of America | C41: Export | G41: Customer40 | H41: =_xlfn.XLOOKUP(G41,'Input Data'!$N$5:$N$64,'Input Data'!$O$5:$O$64,"Not found",0) -> Radcliffe Mercantile
